<sdf version='1.5'>
  <model name='twolink'>
    <link name='link_1'>
      <pose frame=''>0 0 1 0 -0 0</pose>
      <inertial>
        <pose frame=''>0 0 -0.25 0 -0 0</pose>
        <mass>9.375</mass>
        <inertia>
          <ixx>0.197266</ixx>
          <ixy>0</ixy>
          <ixz>0</ixz>
          <iyy>0.197266</iyy>
          <iyz>0</iyz>
          <izz>0.00390625</izz>
        </inertia>
      </inertial>
      <visual name='link_1_visual'>
        <pose frame=''>0 0 -0.25 0 -0 0</pose>
        <geometry>
          <box>
            <size>0.05 0.05 0.5</size>
          </box>
        </geometry>
        <material>
          <script>
            <name>Gazebo/Red</name>
            <uri>__default__</uri>
          </script>
        </material>
      </visual>
      <gravity>1</gravity>
      <velocity_decay/>
      <self_collide>1</self_collide>
    </link>
    <joint name='joint_1' type='revolute'>
      <child>link_1</child>
      <parent>world</parent>
      <axis>
        <xyz>1 0 0</xyz>
        <limit>
          <lower>-1e+16</lower>
          <upper>1e+16</upper>
        </limit>
        <dynamics>
          <damping>50</damping>
          <friction>0</friction>
          <spring_reference>0</spring_reference>
          <spring_stiffness>0</spring_stiffness>
        </dynamics>
        <use_parent_model_frame>1</use_parent_model_frame>
      </axis>
    </joint>
    <link name='link_2'>
      <pose frame=''>0 0 0.5 0 -0 0</pose>
      <inertial>
        <pose frame=''>0 0 -0.25 0 -0 0</pose>
        <mass>9.375</mass>
        <inertia>
          <ixx>0.197266</ixx>
          <ixy>0</ixy>
          <ixz>0</ixz>
          <iyy>0.197266</iyy>
          <iyz>0</iyz>
          <izz>0.00390625</izz>
        </inertia>
      </inertial>
      <visual name='link_2_visual'>
        <pose frame=''>0 0 -0.25 0 -0 0</pose>
        <geometry>
          <box>
            <size>0.05 0.05 0.5</size>
          </box>
        </geometry>
        <material>
          <script>
            <name>Gazebo/Red</name>
            <uri>__default__</uri>
          </script>
        </material>
      </visual>
      <gravity>1</gravity>
      <velocity_decay/>
      <self_collide>1</self_collide>
    </link>
    <joint name='joint_2' type='revolute'>
      <child>link_2</child>
      <parent>link_1</parent>
      <axis>
        <xyz>1 0 0</xyz>
        <limit>
          <lower>-1e+16</lower>
          <upper>1e+16</upper>
        </limit>
        <dynamics>
          <damping>50</damping>
          <friction>0</friction>
          <spring_reference>0</spring_reference>
          <spring_stiffness>0</spring_stiffness>
        </dynamics>
        <use_parent_model_frame>1</use_parent_model_frame>
      </axis>
    </joint>
    <static>0</static>
    <plugin name='gazebo_ros_control' filename='libgazebo_ros_control.so'>
      <robotNamespace>/twolink</robotNamespace>
      <robotSimType>gazebo_ros_control/DefaultRobotHWSim</robotSimType>
    </plugin>
  </model>
</sdf>
